On 2023/03/07 16:11:31, simulate_data.py ran for 0.36 minutes but failed. Error: b'Traceback (most recent call last):\r\n  File "C:\\Users\\Usuario\\Documents\\GitHub\\example_template\\analysis\\source\\simulation\\simulate_data.py", line 43, in <module>\r\n    main()\r\n  File "C:\\Users\\Usuario\\Documents\\GitHub\\example_template\\analysis\\source\\simulation\\simulate_data.py", line 20, in main\r\n    create_data(designpath, outpath, cur_design)\r\n  File "C:\\Users\\Usuario\\Documents\\GitHub\\example_template\\analysis\\source\\simulation\\simulate_data.py", line 39, in create_data\r\n    df.to_csv(outpath + cur_design + \'.csv\', index=False)    \r\n  File "C:\\Users\\Usuario\\AppData\\Local\\Packages\\PythonSoftwareFoundation.Python.3.8_qbz5n2kfra8p0\\LocalCache\\local-packages\\Python38\\site-packages\\pandas\\util\\_decorators.py", line 211, in wrapper\r\n    return func(*args, **kwargs)\r\n  File "C:\\Users\\Usuario\\AppData\\Local\\Packages\\PythonSoftwareFoundation.Python.3.8_qbz5n2kfra8p0\\LocalCache\\local-packages\\Python38\\site-packages\\pandas\\core\\generic.py", line 3721, in to_csv\r\n    return DataFrameRenderer(formatter).to_csv(\r\n  File "C:\\Users\\Usuario\\AppData\\Local\\Packages\\PythonSoftwareFoundation.Python.3.8_qbz5n2kfra8p0\\LocalCache\\local-packages\\Python38\\site-packages\\pandas\\util\\_decorators.py", line 211, in wrapper\r\n    return func(*args, **kwargs)\r\n  File "C:\\Users\\Usuario\\AppData\\Local\\Packages\\PythonSoftwareFoundation.Python.3.8_qbz5n2kfra8p0\\LocalCache\\local-packages\\Python38\\site-packages\\pandas\\io\\formats\\format.py", line 1189, in to_csv\r\n    csv_formatter.save()\r\n  File "C:\\Users\\Usuario\\AppData\\Local\\Packages\\PythonSoftwareFoundation.Python.3.8_qbz5n2kfra8p0\\LocalCache\\local-packages\\Python38\\site-packages\\pandas\\io\\formats\\csvs.py", line 241, in save\r\n    with get_handle(\r\n  File "C:\\Users\\Usuario\\AppData\\Local\\Packages\\PythonSoftwareFoundation.Python.3.8_qbz5n2kfra8p0\\LocalCache\\local-packages\\Python38\\site-packages\\pandas\\io\\common.py", line 735, in get_handle\r\n    check_parent_directory(str(handle))\r\n  File "C:\\Users\\Usuario\\AppData\\Local\\Packages\\PythonSoftwareFoundation.Python.3.8_qbz5n2kfra8p0\\LocalCache\\local-packages\\Python38\\site-packages\\pandas\\io\\common.py", line 598, in check_parent_directory\r\n    raise OSError(rf"Cannot save file into a non-existent directory: \'{parent}\'")\r\nOSError: Cannot save file into a non-existent directory: \'..\\..\\datastore\'\r\n'

On 2023/03/07 16:11:34, summary_stats.py ran for 0.054 minutes but failed. Error: b'Traceback (most recent call last):\r\n  File "C:\\Users\\Usuario\\Documents\\GitHub\\example_template\\analysis\\source\\estimation\\summary_stats.py", line 6, in <module>\r\n    import matplotlib.pyplot as plt\r\nModuleNotFoundError: No module named \'matplotlib\'\r\n'

